Workbook

Sheet Tong_hop
A1: TỔNG HỢP KẾT QUẢ 5 LẦN CHẠY
A2: 2213 ảnh, 5 lớp, 128 chiều; mỗi lần chia lại train/val/test với seed khác và chọn lại siêu tham số trên val. Mọi số trong bảng là công thức tính từ sheet Chi_tiet_5_lan.
A4: Softmax Regression | B4: (dòng 2 đến 6 của Chi_tiet_5_lan)
A5: Chỉ số | B5: Trung bình | C5: Độ lệch chuẩn | D5: Min | E5: Max | F5: Viết vào báo cáo (TB ± ĐLC)
A6: Acc train | B6: =AVERAGE(Chi_tiet_5_lan!N2:N6) | C6: =STDEV(Chi_tiet_5_lan!N2:N6) | D6: =MIN(Chi_tiet_5_lan!N2:N6) | E6: =MAX(Chi_tiet_5_lan!N2:N6) | F6: =FIXED(AVERAGE(Chi_tiet_5_lan!N2:N6),4,TRUE)&" ± "&FIXED(STDEV(Chi_tiet_5_lan!N2:N6),4,TRUE)
A7: Acc val | B7: =AVERAGE(Chi_tiet_5_lan!O2:O6) | C7: =STDEV(Chi_tiet_5_lan!O2:O6) | D7: =MIN(Chi_tiet_5_lan!O2:O6) | E7: =MAX(Chi_tiet_5_lan!O2:O6) | F7: =FIXED(AVERAGE(Chi_tiet_5_lan!O2:O6),4,TRUE)&" ± "&FIXED(STDEV(Chi_tiet_5_lan!O2:O6),4,TRUE)
A8: Acc test | B8: =AVERAGE(Chi_tiet_5_lan!P2:P6) | C8: =STDEV(Chi_tiet_5_lan!P2:P6) | D8: =MIN(Chi_tiet_5_lan!P2:P6) | E8: =MAX(Chi_tiet_5_lan!P2:P6) | F8: =FIXED(AVERAGE(Chi_tiet_5_lan!P2:P6),4,TRUE)&" ± "&FIXED(STDEV(Chi_tiet_5_lan!P2:P6),4,TRUE)
A9: Precision macro test | B9: =AVERAGE(Chi_tiet_5_lan!Q2:Q6) | C9: =STDEV(Chi_tiet_5_lan!Q2:Q6) | D9: =MIN(Chi_tiet_5_lan!Q2:Q6) | E9: =MAX(Chi_tiet_5_lan!Q2:Q6) | F9: =FIXED(AVERAGE(Chi_tiet_5_lan!Q2:Q6),4,TRUE)&" ± "&FIXED(STDEV(Chi_tiet_5_lan!Q2:Q6),4,TRUE)
A10: Recall macro test | B10: =AVERAGE(Chi_tiet_5_lan!R2:R6) | C10: =STDEV(Chi_tiet_5_lan!R2:R6) | D10: =MIN(Chi_tiet_5_lan!R2:R6) | E10: =MAX(Chi_tiet_5_lan!R2:R6) | F10: =FIXED(AVERAGE(Chi_tiet_5_lan!R2:R6),4,TRUE)&" ± "&FIXED(STDEV(Chi_tiet_5_lan!R2:R6),4,TRUE)
A11: F1 macro test | B11: =AVERAGE(Chi_tiet_5_lan!S2:S6) | C11: =STDEV(Chi_tiet_5_lan!S2:S6) | D11: =MIN(Chi_tiet_5_lan!S2:S6) | E11: =MAX(Chi_tiet_5_lan!S2:S6) | F11: =FIXED(AVERAGE(Chi_tiet_5_lan!S2:S6),4,TRUE)&" ± "&FIXED(STDEV(Chi_tiet_5_lan!S2:S6),4,TRUE)
A12: Acc test tự chụp | B12: =AVERAGE(Chi_tiet_5_lan!T2:T6) | C12: =STDEV(Chi_tiet_5_lan!T2:T6) | D12: =MIN(Chi_tiet_5_lan!T2:T6) | E12: =MAX(Chi_tiet_5_lan!T2:T6) | F12: =FIXED(AVERAGE(Chi_tiet_5_lan!T2:T6),4,TRUE)&" ± "&FIXED(STDEV(Chi_tiet_5_lan!T2:T6),4,TRUE)
A13: Acc test RealWaste | B13: =AVERAGE(Chi_tiet_5_lan!U2:U6) | C13: =STDEV(Chi_tiet_5_lan!U2:U6) | D13: =MIN(Chi_tiet_5_lan!U2:U6) | E13: =MAX(Chi_tiet_5_lan!U2:U6) | F13: =FIXED(AVERAGE(Chi_tiet_5_lan!U2:U6),4,TRUE)&" ± "&FIXED(STDEV(Chi_tiet_5_lan!U2:U6),4,TRUE)
A14: Loss train | B14: =AVERAGE(Chi_tiet_5_lan!L2:L6) | C14: =STDEV(Chi_tiet_5_lan!L2:L6) | D14: =MIN(Chi_tiet_5_lan!L2:L6) | E14: =MAX(Chi_tiet_5_lan!L2:L6) | F14: =FIXED(AVERAGE(Chi_tiet_5_lan!L2:L6),4,TRUE)&" ± "&FIXED(STDEV(Chi_tiet_5_lan!L2:L6),4,TRUE)
A15: Loss val | B15: =AVERAGE(Chi_tiet_5_lan!M2:M6) | C15: =STDEV(Chi_tiet_5_lan!M2:M6) | D15: =MIN(Chi_tiet_5_lan!M2:M6) | E15: =MAX(Chi_tiet_5_lan!M2:M6) | F15: =FIXED(AVERAGE(Chi_tiet_5_lan!M2:M6),4,TRUE)&" ± "&FIXED(STDEV(Chi_tiet_5_lan!M2:M6),4,TRUE)
A16: Thời gian tìm + huấn luyện (giây) | B16: =AVERAGE(Chi_tiet_5_lan!W2:W6) | C16: =STDEV(Chi_tiet_5_lan!W2:W6) | D16: =MIN(Chi_tiet_5_lan!W2:W6) | E16: =MAX(Chi_tiet_5_lan!W2:W6) | F16: =FIXED(AVERAGE(Chi_tiet_5_lan!W2:W6),1,TRUE)&" ± "&FIXED(STDEV(Chi_tiet_5_lan!W2:W6),1,TRUE)
A18: SVM | B18: (dòng 7 đến 11 của Chi_tiet_5_lan)
A19: Chỉ số | B19: Trung bình | C19: Độ lệch chuẩn | D19: Min | E19: Max | F19: Viết vào báo cáo (TB ± ĐLC)
A20: Acc train | B20: =AVERAGE(Chi_tiet_5_lan!N7:N11) | C20: =STDEV(Chi_tiet_5_lan!N7:N11) | D20: =MIN(Chi_tiet_5_lan!N7:N11) | E20: =MAX(Chi_tiet_5_lan!N7:N11) | F20: =FIXED(AVERAGE(Chi_tiet_5_lan!N7:N11),4,TRUE)&" ± "&FIXED(STDEV(Chi_tiet_5_lan!N7:N11),4,TRUE)
A21: Acc val | B21: =AVERAGE(Chi_tiet_5_lan!O7:O11) | C21: =STDEV(Chi_tiet_5_lan!O7:O11) | D21: =MIN(Chi_tiet_5_lan!O7:O11) | E21: =MAX(Chi_tiet_5_lan!O7:O11) | F21: =FIXED(AVERAGE(Chi_tiet_5_lan!O7:O11),4,TRUE)&" ± "&FIXED(STDEV(Chi_tiet_5_lan!O7:O11),4,TRUE)
A22: Acc test | B22: =AVERAGE(Chi_tiet_5_lan!P7:P11) | C22: =STDEV(Chi_tiet_5_lan!P7:P11) | D22: =MIN(Chi_tiet_5_lan!P7:P11) | E22: =MAX(Chi_tiet_5_lan!P7:P11) | F22: =FIXED(AVERAGE(Chi_tiet_5_lan!P7:P11),4,TRUE)&" ± "&FIXED(STDEV(Chi_tiet_5_lan!P7:P11),4,TRUE)
A23: Precision macro test | B23: =AVERAGE(Chi_tiet_5_lan!Q7:Q11) | C23: =STDEV(Chi_tiet_5_lan!Q7:Q11) | D23: =MIN(Chi_tiet_5_lan!Q7:Q11) | E23: =MAX(Chi_tiet_5_lan!Q7:Q11) | F23: =FIXED(AVERAGE(Chi_tiet_5_lan!Q7:Q11),4,TRUE)&" ± "&FIXED(STDEV(Chi_tiet_5_lan!Q7:Q11),4,TRUE)
A24: Recall macro test | B24: =AVERAGE(Chi_tiet_5_lan!R7:R11) | C24: =STDEV(Chi_tiet_5_lan!R7:R11) | D24: =MIN(Chi_tiet_5_lan!R7:R11) | E24: =MAX(Chi_tiet_5_lan!R7:R11) | F24: =FIXED(AVERAGE(Chi_tiet_5_lan!R7:R11),4,TRUE)&" ± "&FIXED(STDEV(Chi_tiet_5_lan!R7:R11),4,TRUE)
A25: F1 macro test | B25: =AVERAGE(Chi_tiet_5_lan!S7:S11) | C25: =STDEV(Chi_tiet_5_lan!S7:S11) | D25: =MIN(Chi_tiet_5_lan!S7:S11) | E25: =MAX(Chi_tiet_5_lan!S7:S11) | F25: =FIXED(AVERAGE(Chi_tiet_5_lan!S7:S11),4,TRUE)&" ± "&FIXED(STDEV(Chi_tiet_5_lan!S7:S11),4,TRUE)
A26: Acc test tự chụp | B26: =AVERAGE(Chi_tiet_5_lan!T7:T11) | C26: =STDEV(Chi_tiet_5_lan!T7:T11) | D26: =MIN(Chi_tiet_5_lan!T7:T11) | E26: =MAX(Chi_tiet_5_lan!T7:T11) | F26: =FIXED(AVERAGE(Chi_tiet_5_lan!T7:T11),4,TRUE)&" ± "&FIXED(STDEV(Chi_tiet_5_lan!T7:T11),4,TRUE)
A27: Acc test RealWaste | B27: =AVERAGE(Chi_tiet_5_lan!U7:U11) | C27: =STDEV(Chi_tiet_5_lan!U7:U11) | D27: =MIN(Chi_tiet_5_lan!U7:U11) | E27: =MAX(Chi_tiet_5_lan!U7:U11) | F27: =FIXED(AVERAGE(Chi_tiet_5_lan!U7:U11),4,TRUE)&" ± "&FIXED(STDEV(Chi_tiet_5_lan!U7:U11),4,TRUE)
A28: Loss train | B28: =AVERAGE(Chi_tiet_5_lan!L7:L11) | C28: =STDEV(Chi_tiet_5_lan!L7:L11) | D28: =MIN(Chi_tiet_5_lan!L7:L11) | E28: =MAX(Chi_tiet_5_lan!L7:L11) | F28: =FIXED(AVERAGE(Chi_tiet_5_lan!L7:L11),4,TRUE)&" ± "&FIXED(STDEV(Chi_tiet_5_lan!L7:L11),4,TRUE)
A29: Loss val | B29: =AVERAGE(Chi_tiet_5_lan!M7:M11) | C29: =STDEV(Chi_tiet_5_lan!M7:M11) | D29: =MIN(Chi_tiet_5_lan!M7:M11) | E29: =MAX(Chi_tiet_5_lan!M7:M11) | F29: =FIXED(AVERAGE(Chi_tiet_5_lan!M7:M11),4,TRUE)&" ± "&FIXED(STDEV(Chi_tiet_5_lan!M7:M11),4,TRUE)
A30: Thời gian tìm + huấn luyện (giây) | B30: =AVERAGE(Chi_tiet_5_lan!W7:W11) | C30: =STDEV(Chi_tiet_5_lan!W7:W11) | D30: =MIN(Chi_tiet_5_lan!W7:W11) | E30: =MAX(Chi_tiet_5_lan!W7:W11) | F30: =FIXED(AVERAGE(Chi_tiet_5_lan!W7:W11),1,TRUE)&" ± "&FIXED(STDEV(Chi_tiet_5_lan!W7:W11),1,TRUE)
A32: XGBoost | B32: (dòng 12 đến 16 của Chi_tiet_5_lan)
A33: Chỉ số | B33: Trung bình | C33: Độ lệch chuẩn | D33: Min | E33: Max | F33: Viết vào báo cáo (TB ± ĐLC)
A34: Acc train | B34: =AVERAGE(Chi_tiet_5_lan!N12:N16) | C34: =STDEV(Chi_tiet_5_lan!N12:N16) | D34: =MIN(Chi_tiet_5_lan!N12:N16) | E34: =MAX(Chi_tiet_5_lan!N12:N16) | F34: =FIXED(AVERAGE(Chi_tiet_5_lan!N12:N16),4,TRUE)&" ± "&FIXED(STDEV(Chi_tiet_5_lan!N12:N16),4,TRUE)
A35: Acc val | B35: =AVERAGE(Chi_tiet_5_lan!O12:O16) | C35: =STDEV(Chi_tiet_5_lan!O12:O16) | D35: =MIN(Chi_tiet_5_lan!O12:O16) | E35: =MAX(Chi_tiet_5_lan!O12:O16) | F35: =FIXED(AVERAGE(Chi_tiet_5_lan!O12:O16),4,TRUE)&" ± "&FIXED(STDEV(Chi_tiet_5_lan!O12:O16),4,TRUE)
A36: Acc test | B36: =AVERAGE(Chi_tiet_5_lan!P12:P16) | C36: =STDEV(Chi_tiet_5_lan!P12:P16) | D36: =MIN(Chi_tiet_5_lan!P12:P16) | E36: =MAX(Chi_tiet_5_lan!P12:P16) | F36: =FIXED(AVERAGE(Chi_tiet_5_lan!P12:P16),4,TRUE)&" ± "&FIXED(STDEV(Chi_tiet_5_lan!P12:P16),4,TRUE)
A37: Precision macro test | B37: =AVERAGE(Chi_tiet_5_lan!Q12:Q16) | C37: =STDEV(Chi_tiet_5_lan!Q12:Q16) | D37: =MIN(Chi_tiet_5_lan!Q12:Q16) | E37: =MAX(Chi_tiet_5_lan!Q12:Q16) | F37: =FIXED(AVERAGE(Chi_tiet_5_lan!Q12:Q16),4,TRUE)&" ± "&FIXED(STDEV(Chi_tiet_5_lan!Q12:Q16),4,TRUE)
A38: Recall macro test | B38: =AVERAGE(Chi_tiet_5_lan!R12:R16) | C38: =STDEV(Chi_tiet_5_lan!R12:R16) | D38: =MIN(Chi_tiet_5_lan!R12:R16) | E38: =MAX(Chi_tiet_5_lan!R12:R16) | F38: =FIXED(AVERAGE(Chi_tiet_5_lan!R12:R16),4,TRUE)&" ± "&FIXED(STDEV(Chi_tiet_5_lan!R12:R16),4,TRUE)
A39: F1 macro test | B39: =AVERAGE(Chi_tiet_5_lan!S12:S16) | C39: =STDEV(Chi_tiet_5_lan!S12:S16) | D39: =MIN(Chi_tiet_5_lan!S12:S16) | E39: =MAX(Chi_tiet_5_lan!S12:S16) | F39: =FIXED(AVERAGE(Chi_tiet_5_lan!S12:S16),4,TRUE)&" ± "&FIXED(STDEV(Chi_tiet_5_lan!S12:S16),4,TRUE)
A40: Acc test tự chụp | B40: =AVERAGE(Chi_tiet_5_lan!T12:T16) | C40: =STDEV(Chi_tiet_5_lan!T12:T16) | D40: =MIN(Chi_tiet_5_lan!T12:T16) | E40: =MAX(Chi_tiet_5_lan!T12:T16) | F40: =FIXED(AVERAGE(Chi_tiet_5_lan!T12:T16),4,TRUE)&" ± "&FIXED(STDEV(Chi_tiet_5_lan!T12:T16),4,TRUE)
A41: Acc test RealWaste | B41: =AVERAGE(Chi_tiet_5_lan!U12:U16) | C41: =STDEV(Chi_tiet_5_lan!U12:U16) | D41: =MIN(Chi_tiet_5_lan!U12:U16) | E41: =MAX(Chi_tiet_5_lan!U12:U16) | F41: =FIXED(AVERAGE(Chi_tiet_5_lan!U12:U16),4,TRUE)&" ± "&FIXED(STDEV(Chi_tiet_5_lan!U12:U16),4,TRUE)
A42: Loss train | B42: =AVERAGE(Chi_tiet_5_lan!L12:L16) | C42: =STDEV(Chi_tiet_5_lan!L12:L16) | D42: =MIN(Chi_tiet_5_lan!L12:L16) | E42: =MAX(Chi_tiet_5_lan!L12:L16) | F42: =FIXED(AVERAGE(Chi_tiet_5_lan!L12:L16),4,TRUE)&" ± "&FIXED(STDEV(Chi_tiet_5_lan!L12:L16),4,TRUE)
A43: Loss val | B43: =AVERAGE(Chi_tiet_5_lan!M12:M16) | C43: =STDEV(Chi_tiet_5_lan!M12:M16) | D43: =MIN(Chi_tiet_5_lan!M12:M16) | E43: =MAX(Chi_tiet_5_lan!M12:M16) | F43: =FIXED(AVERAGE(Chi_tiet_5_lan!M12:M16),4,TRUE)&" ± "&FIXED(STDEV(Chi_tiet_5_lan!M12:M16),4,TRUE)
...

Sheet Chi_tiet_5_lan
A1: Mô hình | B1: Lần chạy | C1: Seed | D1: Siêu tham số chọn | E1: Số ảnh train | F1: Số ảnh val | G1: Số ảnh test | H1: Số chiều | I1: PCA giữ phương sai | J1: Epoch/vòng dừng | K1: Loại loss | L1: Loss train | M1: Loss val | N1: Acc train | O1: Acc val | P1: Acc test | Q1: Precision macro test | R1: Recall macro test | S1: F1 macro test | T1: Acc test tự chụp | U1: Acc test RealWaste | V1: Số tổ hợp đã thử | W1: Thời gian tìm + huấn luyện (giây)
A2: Softmax Regression | B2: 1 | C2: 0 | D2: penalty=l1, alpha=0.001, eta0=0.001 | E2: 1549 | F2: 332 | G2: 332 | H2: 128 | I2: 0.84728301 | J2: 151 | K2: log loss | L2: 0.49231012 | M2: 0.66946571 | N2: 0.84118786 | O2: 0.72891566 | P2: 0.77409639 | Q2: 0.7763188 | R2: 0.77443777 | S2: 0.77159306 | T2: 0.70063694 | U2: 0.84 | V2: 30 | W2: 84.300052
A3: Softmax Regression | B3: 2 | C3: 1 | D3: penalty=l1, alpha=0.001, eta0=0.01 | E3: 1549 | F3: 332 | G3: 332 | H3: 128 | I3: 0.84707713 | J3: 8 | K3: log loss | L3: 0.50885139 | M3: 0.69146629 | N3: 0.84118786 | O3: 0.74096386 | P3: 0.77409639 | Q3: 0.77404958 | R3: 0.77394678 | S3: 0.76909482 | T3: 0.70700637 | U3: 0.83428571 | V3: 30 | W3: 75.107925
A4: Softmax Regression | B4: 3 | C4: 2 | D4: penalty=l1, alpha=0.001, eta0=0.01 | E4: 1549 | F4: 332 | G4: 332 | H4: 128 | I4: 0.84670168 | J4: 5 | K4: log loss | L4: 0.52461171 | M4: 0.70955876 | N4: 0.84183344 | O4: 0.74698795 | P4: 0.75301205 | Q4: 0.74742191 | R4: 0.75176133 | S4: 0.7477939 | T4: 0.70063694 | U4: 0.8 | V4: 30 | W4: 74.063936
A5: Softmax Regression | B5: 4 | C5: 3 | D5: penalty=l1, alpha=0.001, eta0=0.001 | E5: 1549 | F5: 332 | G5: 332 | H5: 128 | I5: 0.84820473 | J5: 132 | K5: log loss | L5: 0.47430149 | M5: 0.67422776 | N5: 0.85409942 | O5: 0.78012048 | P5: 0.72289157 | Q5: 0.72154957 | R5: 0.72172283 | S5: 0.71940183 | T5: 0.64556962 | U5: 0.79310345 | V5: 30 | W5: 79.691375
A6: Softmax Regression | B6: 5 | C6: 4 | D6: penalty=l1, alpha=0.001, eta0=0.01 | E6: 1549 | F6: 332 | G6: 332 | H6: 128 | I6: 0.84769517 | J6: 11 | K6: log loss | L6: 0.47534281 | M6: 0.67934028 | N6: 0.85732731 | O6: 0.72590361 | P6: 0.7439759 | Q6: 0.7429449 | R6: 0.74356956 | S6: 0.74037939 | T6: 0.64779874 | U6: 0.83236994 | V6: 30 | W6: 87.817183
A7: SVM | B7: 1 | C7: 0 | D7: kernel=rbf, C=10, gamma=0.01 | E7: 1549 | F7: 332 | G7: 332 | H7: 128 | I7: 0.84728301 | K7: hinge loss | L7: 0 | M7: 0.50908756 | N7: 1 | O7: 0.80120482 | P7: 0.82831325 | Q7: 0.83251438 | R7: 0.82808537 | S7: 0.82940737 | T7: 0.78343949 | U7: 0.86857143 | V7: 30 | W7: 596.37449
A8: SVM | B8: 2 | C8: 1 | D8: kernel=rbf, C=1, gamma=0.01 | E8: 1549 | F8: 332 | G8: 332 | H8: 128 | I8: 0.84707713 | K8: hinge loss | L8: 0.022811583 | M8: 0.51784479 | N8: 0.98902518 | O8: 0.80120482 | P8: 0.81024096 | Q8: 0.81306861 | R8: 0.80981158 | S8: 0.81013034 | T8: 0.73248408 | U8: 0.88 | V8: 30 | W8: 885.37028
A9: SVM | B9: 3 | C9: 2 | D9: kernel=rbf, C=10, gamma=0.01 | E9: 1549 | F9: 332 | G9: 332 | H9: 128 | I9: 0.84670168 | K9: hinge loss | L9: 0 | M9: 0.62179905 | N9: 1 | O9: 0.77710843 | P9: 0.82228916 | Q9: 0.82723163 | R9: 0.82101709 | S9: 0.82034074 | T9: 0.78343949 | U9: 0.85714286 | V9: 30 | W9: 1168.2116
A10: SVM | B10: 4 | C10: 3 | D10: kernel=rbf, C=1, gamma=0.01 | E10: 1549 | F10: 332 | G10: 332 | H10: 128 | I10: 0.84820473 | K10: hinge loss | L10: 0.026852575 | M10: 0.49238077 | N10: 0.98773402 | O10: 0.80421687 | P10: 0.81325301 | Q10: 0.81282185 | R10: 0.81215371 | S10: 0.81053739 | T10: 0.75949367 | U10: 0.86206897 | V10: 30 | W10: 1566.7737
A11: SVM | B11: 5 | C11: 4 | D11: kernel=rbf, C=10, gamma=scale | E11: 1549 | F11: 332 | G11: 332 | H11: 128 | I11: 0.84769517 | K11: hinge loss | L11: 0 | M11: 0.53580423 | N11: 1 | O11: 0.78313253 | P11: 0.80120482 | Q11: 0.80007799 | R11: 0.80056014 | S11: 0.79944231 | T11: 0.72955975 | U11: 0.86705202 | V11: 30 | W11: 1239.0765
A12: XGBoost | B12: 1 | C12: 0 | D12: max_depth=7, learning_rate=0.05, subsample=0.7, colsample_bytree=0.5 | E12: 1549 | F12: 332 | G12: 332 | H12: 128 | I12: 0.84728301 | J12: 411 | K12: log loss | L12: 0.019086984 | M12: 0.60794641 | N12: 1 | O12: 0.75 | P12: 0.80120482 | Q12: 0.80161143 | R12: 0.80098805 | S12: 0.80085224 | T12: 0.72611465 | U12: 0.86857143 | V12: 36 | W12: 278.07042
A13: XGBoost | B13: 2 | C13: 1 | D13: max_depth=7, learning_rate=0.05, subsample=0.7, colsample_bytree=0.5 | E13: 1549 | F13: 332 | G13: 332 | H13: 128 | I13: 0.84707713 | J13: 287 | K13: log loss | L13: 0.030268032 | M13: 0.64250132 | N13: 1 | O13: 0.75 | P13: 0.79819277 | Q13: 0.79766275 | R13: 0.79792328 | S13: 0.79280963 | T13: 0.7388535 | U13: 0.85142857 | V13: 36 | W13: 218.7592
A14: XGBoost | B14: 3 | C14: 2 | D14: max_depth=7, learning_rate=0.1, subsample=0.7, colsample_bytree=0.5 | E14: 1549 | F14: 332 | G14: 332 | H14: 128 | I14: 0.84670168 | J14: 174 | K14: log loss | L14: 0.023394959 | M14: 0.62685474 | N14: 1 | O14: 0.76204819 | P14: 0.78614458 | Q14: 0.78579738 | R14: 0.78551158 | S14: 0.7834098 | T14: 0.70700637 | U14: 0.85714286 | V14: 36 | W14: 240.06546
A15: XGBoost | B15: 4 | C15: 3 | D15: max_depth=7, learning_rate=0.05, subsample=0.7, colsample_bytree=0.5 | E15: 1549 | F15: 332 | G15: 332 | H15: 128 | I15: 0.84820473 | J15: 444 | K15: log loss | L15: 0.017523278 | M15: 0.58281165 | N15: 1 | O15: 0.78012048 | P15: 0.79819277 | Q15: 0.79647834 | R15: 0.79754373 | S15: 0.79569227 | T15: 0.74683544 | U15: 0.84482759 | V15: 36 | W15: 332.57781
A16: XGBoost | B16: 5 | C16: 4 | D16: max_depth=5, learning_rate=0.05, subsample=0.7, colsample_bytree=1.0 | E16: 1549 | F16: 332 | G16: 332 | H16: 128 | I16: 0.84769517 | J16: 399 | K16: log loss | L16: 0.021995544 | M16: 0.54719524 | N16: 1 | O16: 0.78915663 | P16: 0.78614458 | Q16: 0.78816451 | R16: 0.78577184 | S16: 0.78420054 | T16: 0.72955975 | U16: 0.83815029 | V16: 36 | W16: 372.01373

Sheet Sieu_tham_so_TB
A1: Mô hình | B1: Siêu tham số | C1: Số lần | D1: Acc train TB | E1: Acc val TB | F1: Acc val ĐLC | G1: Loss val TB | H1: Loss val ĐLC | I1: Epoch/vòng dừng TB | J1: Thời gian TB (giây) | K1: Số lần được chọn
A2: Softmax Regression | B2: penalty=l2, alpha=0.1, eta0=0.0001 | C2: 5 | D2: 0.83292447 | E2: 0.74879518 | F2: 0.011587581 | G2: 0.89879124 | H2: 0.0045732848 | I2: 200 | J2: 3.9025898 | K2: 0
A3: Softmax Regression | B3: penalty=l1, alpha=0.001, eta0=0.0001 | C3: 5 | D3: 0.83795997 | E3: 0.74879518 | F3: 0.017640422 | G3: 0.73990888 | H3: 0.0070388623 | I3: 200 | J3: 5.0513494 | K3: 0
A4: Softmax Regression | B4: penalty=l2, alpha=0.01, eta0=0.01 | C4: 5 | D4: 0.84364106 | E4: 0.74819277 | F4: 0.017381371 | G4: 0.69401994 | H4: 0.012615687 | I4: 10.8 | J4: 0.52145042 | K4: 0
A5: Softmax Regression | B5: penalty=l2, alpha=0.1, eta0=0.001 | C5: 5 | D5: 0.83331181 | E5: 0.74759036 | F5: 0.01336888 | G5: 0.88548362 | H5: 0.0045480385 | I5: 56.6 | J5: 1.4162401 | K5: 0
A6: Softmax Regression | B6: penalty=l2, alpha=0.01, eta0=0.001 | C6: 5 | D6: 0.84764364 | E6: 0.74638554 | F6: 0.022879674 | G6: 0.69862993 | H6: 0.012853226 | I6: 127 | J6: 2.7087251 | K6: 0
A7: Softmax Regression | B7: penalty=l1, alpha=0.001, eta0=0.001 | C7: 5 | D7: 0.85022595 | E7: 0.74638554 | F7: 0.020911512 | G7: 0.68779255 | H7: 0.018672064 | I7: 99.4 | J7: 2.8599393 | K7: 2
A8: Softmax Regression | B8: penalty=l2, alpha=1e-05, eta0=0.0001 | C8: 5 | D8: 0.83950936 | E8: 0.7439759 | F8: 0.015505467 | G8: 0.73846147 | H8: 0.0058607174 | I8: 200 | J8: 4.1931743 | K8: 0
A9: Softmax Regression | B9: penalty=l2, alpha=0.0001, eta0=0.0001 | C9: 5 | D9: 0.83950936 | E9: 0.7439759 | F9: 0.015505467 | G9: 0.73846147 | H9: 0.0058607174 | I9: 200 | J9: 3.9543956 | K9: 0
A10: Softmax Regression | B10: penalty=l2, alpha=0.001, eta0=0.0001 | C10: 5 | D10: 0.83963848 | E10: 0.7439759 | F10: 0.015505467 | G10: 0.73998011 | H10: 0.0058030731 | I10: 200 | J10: 3.8591508 | K10: 0
A11: Softmax Regression | B11: penalty=l2, alpha=0.001, eta0=0.01 | C11: 5 | D11: 0.84609425 | E11: 0.7439759 | F11: 0.02053943 | G11: 0.69577368 | H11: 0.013630942 | I11: 7.6 | J11: 0.44123635 | K11: 0
A12: Softmax Regression | B12: penalty=l2, alpha=0.01, eta0=0.0001 | C12: 5 | D12: 0.83950936 | E12: 0.7439759 | F12: 0.016359609 | G12: 0.75257906 | H12: 0.0054456039 | I12: 200 | J12: 3.8491502 | K12: 0
A13: Softmax Regression | B13: penalty=l1, alpha=1e-05, eta0=0.0001 | C13: 5 | D13: 0.83950936 | E13: 0.7439759 | F13: 0.015505467 | G13: 0.73846812 | H13: 0.0058750017 | I13: 200 | J13: 5.0610166 | K13: 0
... A31: Softmax Regression | B31: penalty=l1, alpha=0.1, eta0=0.001 | C31: 5 | D31: 0.50587476 | E31: 0.5 | F31: 0.017946348 | G31: 1.340723 | H31: 0.0044016506 | I31: 58 | J31: 2.8340271 | K31: 0
A32: SVM | B32: kernel=rbf, C=10, gamma=0.01 | C32: 5 | D32: 1 | E32: 0.78975904 | F32: 0.01302515 | G32: 0.54548021 | H32: 0.04833504 | J32: 1.5238342 | K32: 2
A33: SVM | B33: kernel=rbf, C=100, gamma=0.01 | C33: 5 | D33: 1 | E33: 0.78975904 | F33: 0.01302515 | G33: 0.54548021 | H33: 0.04833504 | J33: 1.4753095 | K33: 0
A34: SVM | B34: kernel=rbf, C=1000, gamma=0.01 | C34: 5 | D34: 1 | E34: 0.78975904 | F34: 0.01302515 | G34: 0.54548021 | H34: 0.04833504 | J34: 1.5186897 | K34: 0
A35: SVM | B35: kernel=rbf, C=1, gamma=0.01 | C35: 5 | D35: 0.98812137 | E35: 0.7873494 | F35: 0.0171184 | G35: 0.55234489 | H35: 0.061966998 | J35: 1.4273039 | K35: 2
A36: SVM | B36: kernel=rbf, C=1, gamma=scale | C36: 5 | D36: 0.9767592 | E36: 0.78433735 | F36: 0.016164347 | G36: 0.55894367 | H36: 0.061042261 | J36: 1.4260579 | K36: 0
A37: SVM | B37: kernel=rbf, C=10, gamma=scale | C37: 5 | D37: 1 | E37: 0.78433735 | F37: 0.0045679973 | G37: 0.55714722 | H37: 0.040527294 | J37: 1.5025289 | K37: 1
A38: SVM | B38: kernel=rbf, C=100, gamma=scale | C38: 5 | D38: 1 | E38: 0.78433735 | F38: 0.0045679973 | G38: 0.55714722 | H38: 0.040527294 | J38: 1.4938101 | K38: 0
A39: SVM | B39: kernel=rbf, C=1000, gamma=scale | C39: 5 | D39: 1 | E39: 0.78433735 | F39: 0.0045679973 | G39: 0.55714722 | H39: 0.040527294 | J39: 1.5252327 | K39: 0
A40: SVM | B40: kernel=rbf, C=1, gamma=0.001 | C40: 5 | D40: 0.83705617 | E40: 0.74939759 | F40: 0.011934706 | G40: 0.64615476 | H40: 0.045786095 | J40: 1.3062496 | K40: 0
A41: SVM | B41: kernel=rbf, C=1000, gamma=0.001 | C41: 5 | D41: 1 | E41: 0.74759036 | F41: 0.011934706 | G41: 0.6519809 | H41: 0.04344723 | J41: 1.1097749 | K41: 0
A42: SVM | B42: kernel=rbf, C=100, gamma=0.001 | C42: 5 | D42: 0.99909619 | E42: 0.74578313 | F42: 0.0098986004 | G42: 0.65826358 | H42: 0.044069297 | J42: 1.0754317 | K42: 0
A43: SVM | B43: kernel=rbf, C=10, gamma=0.0001 | C43: 5 | D43: 0.82453196 | E43: 0.74277108 | F43: 0.0086776267 | G43: 0.66490781 | H43: 0.0342936 | J43: 1.3111609 | K43: 0
... A61: SVM | B61: kernel=rbf, C=1, gamma=0.0001 | C61: 5 | D61: 0.20271143 | E61: 0.20240964 | F61: 0.0013470289 | G61: 2.9734184 | H61: 0.0048867692 | J61: 1.4677449 | K61: 0
A62: XGBoost | B62: max_depth=5, learning_rate=0.05, subsample=0.7, colsample_bytree=0.5 | C62: 5 | D62: 1 | E62: 0.77048193 | F62: 0.0074999395 | G62: 0.61922178 | H62: 0.028012288 | I62: 430 | J62: 13.047381 | K62: 0
A63: XGBoost | B63: max_depth=7, learning_rate=0.05, subsample=0.7, colsample_bytree=1.0 | C63: 5 | D63: 1 | E63: 0.76927711 | F63: 0.014694351 | G63: 0.62223712 | H63: 0.039351516 | I63: 334.8 | J63: 17.103722 | K63: 0
A64: XGBoost | B64: max_depth=5, learning_rate=0.1, subsample=0.7, colsample_bytree=0.5 | C64: 5 | D64: 1 | E64: 0.76746988 | F64: 0.012308926 | G64: 0.62654501 | H64: 0.03766338 | I64: 228.2 | J64: 7.1902029 | K64: 0
A65: XGBoost | B65: max_depth=3, learning_rate=0.1, subsample=1.0, colsample_bytree=0.5 | C65: 5 | D65: 1 | E65: 0.76686747 | F65: 0.018882443 | G65: 0.64534391 | H65: 0.060094366 | I65: 328 | J65: 7.197345 | K65: 0
A66: XGBoost | B66: max_depth=3, learning_rate=0.05, subsample=0.7, colsample_bytree=0.5 | C66: 5 | D66: 1 | E66: 0.76626506 | F66: 0.0094292023 | G66: 0.63113971 | H66: 0.043757662 | I66: 594.6 | J66: 12.28094 | K66: 0
A67: XGBoost | B67: max_depth=5, learning_rate=0.1, subsample=1.0, colsample_bytree=0.5 | C67: 5 | D67: 1 | E67: 0.76626506 | F67: 0.021678379 | G67: 0.62901683 | H67: 0.044946263 | I67: 184.6 | J67: 6.2107169 | K67: 0
A68: XGBoost | B68: max_depth=7, learning_rate=0.05, subsample=1.0, colsample_bytree=0.5 | C68: 5 | D68: 1 | E68: 0.76566265 | F68: 0.019215829 | G68: 0.62500884 | H68: 0.042452414 | I68: 359.4 | J68: 14.17987 | K68: 0
A69: XGBoost | B69: max_depth=5, learning_rate=0.1, subsample=1.0, colsample_bytree=1.0 | C69: 5 | D69: 1 | E69: 0.76506024 | F69: 0.022337947 | G69: 0.64822019 | H69: 0.055041793 | I69: 177 | J69: 7.1405819 | K69: 0
A70: XGBoost | B70: max_depth=5, learning_rate=0.1, subsample=0.7, colsample_bytree=1.0 | C70: 5 | D70: 1 | E70: 0.76445783 | F70: 0.019215829 | G70: 0.63505342 | H70: 0.039105133 | I70: 186.6 | J70: 6.8931786 | K70: 0
A71: XGBoost | B71: max_depth=7, learning_rate=0.05, subsample=0.7, colsample_bytree=0.5 | C71: 5 | D71: 1 | E71: 0.76445783 | F71: 0.013868511 | G71: 0.60576043 | H71: 0.032573074 | I71: 411.6 | J71: 16.30732 | K71: 3
A72: XGBoost | B72: max_depth=7, learning_rate=0.1, subsample=0.7, colsample_bytree=0.5 | C72: 5 | D72: 1 | E72: 0.76325301 | F72: 0.0050401206 | G72: 0.62052641 | H72: 0.029650332 | I72: 220 | J72: 8.3858986 | K72: 1
A73: XGBoost | B73: max_depth=5, learning_rate=0.05, subsample=1.0, colsample_bytree=0.5 | C73: 5 | D73: 1 | E73: 0.7626506 | F73: 0.020583554 | G73: 0.63118173 | H73: 0.046899186 | I73: 370.2 | J73: 11.011003 | K73: 0
... A97: XGBoost | B97: max_depth=5, learning_rate=0.3, subsample=0.7, colsample_bytree=0.5 | C97: 5 | D97: 1 | E97: 0.74156627 | F97: 0.01668903 | G97: 0.66388521 | H97: 0.038470697 | I97: 84.8 | J97: 3.1056506 | K97: 0

Sheet Anh_huong_tung_tham_so
A1: Mô hình | B1: Tham số | C1: Giá trị | D1: Số tổ hợp | E1: Acc val TB tốt nhất | F1: Acc val TB trung bình | G1: Acc train TB (tại tổ hợp tốt nhất)
A2: Softmax Regression | B2: penalty | C2: l2 | D2: 15 | E2: 0.74879518 | F2: 0.74425703 | G2: 0.83292447
A3: Softmax Regression | B3: penalty | C3: l1 | D3: 15 | E3: 0.74879518 | F3: 0.69473896 | G3: 0.83795997
A4: Softmax Regression | B4: alpha | C4: 1e-05 | D4: 6 | E4: 0.7439759 | F4: 0.74277108 | G4: 0.83950936
A5: Softmax Regression | B5: alpha | C5: 0.0001 | D5: 6 | E5: 0.7439759 | F5: 0.74307229 | G5: 0.83950936
A6: Softmax Regression | B6: alpha | C6: 0.001 | D6: 6 | E6: 0.74879518 | F6: 0.74508032 | G6: 0.83795997
A7: Softmax Regression | B7: alpha | C7: 0.01 | D7: 6 | E7: 0.74819277 | F7: 0.74246988 | G7: 0.84364106
A8: Softmax Regression | B8: alpha | C8: 0.1 | D8: 6 | E8: 0.74879518 | F8: 0.62409639 | G8: 0.83292447
A9: Softmax Regression | B9: eta0 | C9: 0.0001 | D9: 10 | E9: 0.74879518 | F9: 0.72024096 | G9: 0.83292447
A10: Softmax Regression | B10: eta0 | C10: 0.001 | D10: 10 | E10: 0.74759036 | F10: 0.71909639 | G10: 0.83331181
A11: Softmax Regression | B11: eta0 | C11: 0.01 | D11: 10 | E11: 0.74819277 | F11: 0.71915663 | G11: 0.84364106
A12: SVM | B12: kernel | C12: linear | D12: 5 | E12: 0.71626506 | F12: 0.69096386 | G12: 0.89748225
A13: SVM | B13: kernel | C13: rbf | D13: 25 | E13: 0.78975904 | F13: 0.56253012 | G13: 1
... A34: XGBoost | B34: colsample_bytree | C34: 1.0 | D34: 18 | E34: 0.76927711 | F34: 0.75565596 | G34: 1

Sheet Sieu_tham_so_chi_tiet
A1: Lần chạy | B1: Seed | C1: Mô hình | D1: Siêu tham số | E1: Epoch/vòng dừng | F1: Loss train | G1: Loss val | H1: Acc train | I1: Acc val | J1: Thời gian (giây)
A2: 1 | B2: 0 | C2: Softmax Regression | D2: penalty=l2, alpha=1e-05, eta0=0.0001 | E2: 200 | F2: 0.60615608 | G2: 0.74003507 | H2: 0.82698515 | I2: 0.72289157 | J2: 3.9807477
A3: 1 | B3: 0 | C3: Softmax Regression | D3: penalty=l2, alpha=1e-05, eta0=0.001 | E3: 87 | F3: 0.49610192 | G3: 0.68422907 | H3: 0.8431246 | I3: 0.70783133 | J3: 1.9209089
A4: 1 | B4: 0 | C4: Softmax Regression | D4: penalty=l2, alpha=1e-05, eta0=0.01 | E4: 8 | F4: 0.50743278 | G4: 0.68363407 | H4: 0.83666882 | I4: 0.71084337 | J4: 0.42044067
A5: 1 | B5: 0 | C5: Softmax Regression | D5: penalty=l2, alpha=0.0001, eta0=0.0001 | E5: 200 | F5: 0.60615608 | G5: 0.74003507 | H5: 0.82698515 | I5: 0.72289157 | J5: 3.8235223
A6: 1 | B6: 0 | C6: Softmax Regression | D6: penalty=l2, alpha=0.0001, eta0=0.001 | E6: 87 | F6: 0.49656334 | G6: 0.68405437 | H6: 0.8431246 | I6: 0.70783133 | J6: 1.9308715
A7: 1 | B7: 0 | C7: Softmax Regression | D7: penalty=l2, alpha=0.0001, eta0=0.01 | E7: 8 | F7: 0.50776466 | G7: 0.68350416 | H7: 0.83666882 | I7: 0.71385542 | J7: 0.4217484
A8: 1 | B8: 0 | C8: Softmax Regression | D8: penalty=l2, alpha=0.001, eta0=0.0001 | E8: 200 | F8: 0.60865925 | G8: 0.74173165 | H8: 0.82827631 | I8: 0.72289157 | J8: 3.9051485
A9: 1 | B9: 0 | C9: Softmax Regression | D9: penalty=l2, alpha=0.001, eta0=0.001 | E9: 113 | F9: 0.4913417 | G9: 0.68200998 | H9: 0.8431246 | I9: 0.71084337 | J9: 2.6822605
A10: 1 | B10: 0 | C10: Softmax Regression | D10: penalty=l2, alpha=0.001, eta0=0.01 | E10: 8 | F10: 0.51121733 | G10: 0.68252202 | H10: 0.83473209 | I10: 0.71385542 | J10: 0.42619228
A11: 1 | B11: 0 | C11: Softmax Regression | D11: penalty=l2, alpha=0.01, eta0=0.0001 | E11: 200 | F11: 0.62800901 | G11: 0.75552149 | H11: 0.82892189 | I11: 0.71987952 | J11: 3.763916
A12: 1 | B12: 0 | C12: Softmax Regression | D12: penalty=l2, alpha=0.01, eta0=0.001 | E12: 151 | F12: 0.53533814 | G12: 0.69067328 | H12: 0.83602324 | I12: 0.71987952 | J12: 3.2188978
A13: 1 | B13: 0 | C13: Softmax Regression | D13: penalty=l2, alpha=0.01, eta0=0.01 | E13: 13 | F13: 0.54483857 | G13: 0.68920073 | H13: 0.82956746 | I13: 0.73493976 | J13: 0.53170753
... A31: 1 | B31: 0 | C31: Softmax Regression | D31: penalty=l1, alpha=0.1, eta0=0.01 | E31: 18 | F31: 1.3325644 | G31: 1.3391996 | H31: 0.50419626 | I31: 0.51204819 | J31: 1.2534893
A32: 1 | B32: 0 | C32: SVM | D32: kernel=linear, C=0.1, gamma=- | F32: 0.23884846 | G32: 0.74028267 | H32: 0.8896062 | I32: 0.71987952 | J32: 0.44035029
A33: 1 | B33: 0 | C33: SVM | D33: kernel=linear, C=1, gamma=- | F33: 0.14054707 | G33: 0.80731686 | H33: 0.93415107 | I33: 0.67771084 | J33: 1.2654328
A34: 1 | B34: 0 | C34: SVM | D34: kernel=linear, C=10, gamma=- | F34: 0.09719152 | G34: 0.79658065 | H34: 0.95674629 | I34: 0.68674699 | J34: 6.582314
A35: 1 | B35: 0 | C35: SVM | D35: kernel=linear, C=100, gamma=- | F35: 0.081887699 | G35: 0.81621392 | H35: 0.9651388 | I35: 0.68373494 | J35: 54.135911
A36: 1 | B36: 0 | C36: SVM | D36: kernel=linear, C=1000, gamma=- | F36: 0.077577376 | G36: 0.81074265 | H36: 0.96707553 | I36: 0.68072289 | J36: 501.55412
A37: 1 | B37: 0 | C37: SVM | D37: kernel=rbf, C=0.1, gamma=scale | F37: 1.5153781 | G37: 1.7634741 | H37: 0.44738541 | I37: 0.43072289 | J37: 1.2894442
A38: 1 | B38: 0 | C38: SVM | D38: kernel=rbf, C=0.1, gamma=0.0001 | F38: 3.0363395 | G38: 3.0412244 | H38: 0.20271143 | I38: 0.20180723 | J38: 1.2747695
A39: 1 | B39: 0 | C39: SVM | D39: kernel=rbf, C=0.1, gamma=0.001 | F39: 2.981518 | G39: 2.9917089 | H39: 0.20271143 | I39: 0.20180723 | J39: 1.3038375
A40: 1 | B40: 0 | C40: SVM | D40: kernel=rbf, C=0.1, gamma=0.01 | F40: 1.927215 | G40: 2.1304573 | H40: 0.36152356 | I40: 0.36445783 | J40: 1.4116318
A41: 1 | B41: 0 | C41: SVM | D41: kernel=rbf, C=0.1, gamma=0.1 | F41: 3.0094898 | G41: 3.0415963 | H41: 0.20271143 | I41: 0.20180723 | J41: 1.3362358
A42: 1 | B42: 0 | C42: SVM | D42: kernel=rbf, C=1, gamma=scale | F42: 0.049045936 | G42: 0.51943645 | H42: 0.9767592 | I42: 0.79518072 | J42: 1.3353384
A43: 1 | B43: 0 | C43: SVM | D43: kernel=rbf, C=1, gamma=0.0001 | F43: 2.967014 | G43: 2.9774277 | H43: 0.20271143 | I43: 0.20180723 | J43: 1.5671189
... A61: 1 | B61: 0 | C61: SVM | D61: kernel=rbf, C=1000, gamma=0.1 | F61: 0 | G61: 2.5865395 | H61: 1 | I61: 0.28313253 | J61: 1.3855779
A62: 1 | B62: 0 | C62: XGBoost | D62: max_depth=3, learning_rate=0.05, subsample=0.7, colsample_bytree=0.5 | E62: 589 | F62: 0.057124318 | G62: 0.64310258 | H62: 1 | I62: 0.76807229 | J62: 12.210093
A63: 1 | B63: 0 | C63: XGBoost | D63: max_depth=3, learning_rate=0.05, subsample=0.7, colsample_bytree=1.0 | E63: 553 | F63: 0.0509895 | G63: 0.64132864 | H63: 1 | I63: 0.73493976 | J63: 13.94761
A64: 1 | B64: 0 | C64: XGBoost | D64: max_depth=3, learning_rate=0.05, subsample=1.0, colsample_bytree=0.5 | E64: 542 | F64: 0.070815209 | G64: 0.65252462 | H64: 1 | I64: 0.72891566 | J64: 10.778104
A65: 1 | B65: 0 | C65: XGBoost | D65: max_depth=3, learning_rate=0.05, subsample=1.0, colsample_bytree=1.0 | E65: 551 | F65: 0.057200291 | G65: 0.69714261 | H65: 1 | I65: 0.73795181 | J65: 14.324131
A66: 1 | B66: 0 | C66: XGBoost | D66: max_depth=3, learning_rate=0.1, subsample=0.7, colsample_bytree=0.5 | E66: 379 | F66: 0.032332992 | G66: 0.6410013 | H66: 1 | I66: 0.7560241 | J66: 12.384484
A67: 1 | B67: 0 | C67: XGBoost | D67: max_depth=3, learning_rate=0.1, subsample=0.7, colsample_bytree=1.0 | E67: 285 | F67: 0.047265684 | G67: 0.66485716 | H67: 1 | I67: 0.74096386 | J67: 14.877213
A68: 1 | B68: 0 | C68: XGBoost | D68: max_depth=3, learning_rate=0.1, subsample=1.0, colsample_bytree=0.5 | E68: 305 | F68: 0.051654206 | G68: 0.65918907 | H68: 1 | I68: 0.74096386 | J68: 9.0833049
A69: 1 | B69: 0 | C69: XGBoost | D69: max_depth=3, learning_rate=0.1, subsample=1.0, colsample_bytree=1.0 | E69: 239 | F69: 0.077702155 | G69: 0.69558752 | H69: 1 | I69: 0.72289157 | J69: 8.8336616
A70: 1 | B70: 0 | C70: XGBoost | D70: max_depth=3, learning_rate=0.3, subsample=0.7, colsample_bytree=0.5 | E70: 105 | F70: 0.047140161 | G70: 0.70127326 | H70: 1 | I70: 0.74096386 | J70: 3.0392358
A71: 1 | B71: 0 | C71: XGBoost | D71: max_depth=3, learning_rate=0.3, subsample=0.7, colsample_bytree=1.0 | E71: 123 | F71: 0.026236804 | G71: 0.72771707 | H71: 1 | I71: 0.7560241 | J71: 3.1946986
A72: 1 | B72: 0 | C72: XGBoost | D72: max_depth=3, learning_rate=0.3, subsample=1.0, colsample_bytree=0.5 | E72: 108 | F72: 0.043053355 | G72: 0.69438125 | H72: 1 | I72: 0.73493976 | J72: 2.5966358
A73: 1 | B73: 0 | C73: XGBoost | D73: max_depth=3, learning_rate=0.3, subsample=1.0, colsample_bytree=1.0 | E73: 76 | F73: 0.076648358 | G73: 0.69812001 | H73: 1 | I73: 0.72891566 | J73: 2.2169662
... A127: 2 | B127: 1 | C127: Softmax Regression | D127: penalty=l1, alpha=0.1, eta0=0.01 | E127: 4 | F127: 1.3325291 | G127: 1.3321824 | H127: 0.51194319 | I127: 0.51506024 | J127: 0.75169086
...

Sheet Theo_lop
A1: Mô hình | B1: Lần chạy | C1: Lớp | D1: Precision | E1: Recall | F1: F1 | G1: Số ảnh test
A2: Softmax Regression | B2: 1 | C2: giay | D2: 0.73972603 | E2: 0.79411765 | F2: 0.76595745 | G2: 68
A3: Softmax Regression | B3: 1 | C3: nhua | D3: 0.69230769 | E3: 0.53731343 | F3: 0.60504202 | G3: 67
A4: Softmax Regression | B4: 1 | C4: huu_co | D4: 0.98412698 | E4: 0.92537313 | F4: 0.95384615 | G4: 67
A5: Softmax Regression | B5: 1 | C5: kim_loai | D5: 0.76923077 | E5: 0.76923077 | F5: 0.76923077 | G5: 65
A6: Softmax Regression | B6: 1 | C6: khac | D6: 0.69620253 | E6: 0.84615385 | F6: 0.76388889 | G6: 65
A7: SVM | B7: 1 | C7: giay | D7: 0.86567164 | E7: 0.85294118 | F7: 0.85925926 | G7: 68
A8: SVM | B8: 1 | C8: nhua | D8: 0.72058824 | E8: 0.73134328 | F8: 0.72592593 | G8: 67
A9: SVM | B9: 1 | C9: huu_co | D9: 0.98412698 | E9: 0.92537313 | F9: 0.95384615 | G9: 67
A10: SVM | B10: 1 | C10: kim_loai | D10: 0.85245902 | E10: 0.8 | F10: 0.82539683 | G10: 65
A11: SVM | B11: 1 | C11: khac | D11: 0.73972603 | E11: 0.83076923 | F11: 0.7826087 | G11: 65
A12: XGBoost | B12: 1 | C12: giay | D12: 0.77027027 | E12: 0.83823529 | F12: 0.8028169 | G12: 68
A13: XGBoost | B13: 1 | C13: nhua | D13: 0.671875 | E13: 0.64179104 | F13: 0.65648855 | G13: 67
... A76: XGBoost | B76: 5 | C76: khac | D76: 0.80701754 | E76: 0.70769231 | F76: 0.75409836 | G76: 65

Sheet Ma_tran_nham_lan
A1: Mô hình | B1: Lần chạy | C1: Thực tế | D1: Dự đoán giay | E1: Dự đoán nhua | F1: Dự đoán huu_co | G1: Dự đoán kim_loai | H1: Dự đoán khac
A2: Softmax Regression | B2: 1 | C2: giay | D2: 54 | E2: 10 | F2: 0 | G2: 1 | H2: 3
A3: Softmax Regression | B3: 1 | C3: nhua | D3: 12 | E3: 36 | F3: 1 | G3: 7 | H3: 11
A4: Softmax Regression | B4: 1 | C4: huu_co | D4: 2 | E4: 1 | F4: 62 | G4: 1 | H4: 1
A5: Softmax Regression | B5: 1 | C5: kim_loai | D5: 4 | E5: 2 | F5: 0 | G5: 50 | H5: 9
A6: Softmax Regression | B6: 1 | C6: khac | D6: 1 | E6: 3 | F6: 0 | G6: 6 | H6: 55
A7: SVM | B7: 1 | C7: giay | D7: 58 | E7: 7 | F7: 0 | G7: 1 | H7: 2
A8: SVM | B8: 1 | C8: nhua | D8: 5 | E8: 49 | F8: 1 | G8: 3 | H8: 9
A9: SVM | B9: 1 | C9: huu_co | D9: 0 | E9: 2 | F9: 62 | G9: 0 | H9: 3
A10: SVM | B10: 1 | C10: kim_loai | D10: 3 | E10: 5 | F10: 0 | G10: 52 | H10: 5
A11: SVM | B11: 1 | C11: khac | D11: 1 | E11: 5 | F11: 0 | G11: 5 | H11: 54
A12: XGBoost | B12: 1 | C12: giay | D12: 57 | E12: 9 | F12: 0 | G12: 1 | H12: 1
A13: XGBoost | B13: 1 | C13: nhua | D13: 9 | E13: 43 | F13: 1 | G13: 5 | H13: 9
... A76: XGBoost | B76: 5 | C76: khac | D76: 2 | E76: 5 | F76: 4 | G76: 8 | H76: 46

Sheet Loss_theo_epoch
A1: Mô hình | B1: Lần chạy | C1: Epoch/vòng | D1: Loss train | E1: Loss val | F1: Được chọn (early stopping)
A2: Softmax Regression | B2: 1 | C2: 1 | D2: 1.332665 | E2: 1.361805
A3: Softmax Regression | B3: 1 | C3: 2 | D3: 1.1527901 | E3: 1.2009012
A4: Softmax Regression | B4: 1 | C4: 3 | D4: 1.0322607 | E4: 1.0943
A5: Softmax Regression | B5: 1 | C5: 4 | D5: 0.94753472 | E5: 1.0196438
A6: Softmax Regression | B6: 1 | C6: 5 | D6: 0.88534115 | E6: 0.96519229
A7: Softmax Regression | B7: 1 | C7: 6 | D7: 0.83758492 | E7: 0.92391136
A8: Softmax Regression | B8: 1 | C8: 7 | D8: 0.79982753 | E8: 0.89161495
A9: Softmax Regression | B9: 1 | C9: 8 | D9: 0.76937369 | E9: 0.86557899
A10: Softmax Regression | B10: 1 | C10: 9 | D10: 0.74422034 | E10: 0.84449646
A11: Softmax Regression | B11: 1 | C11: 10 | D11: 0.72313551 | E11: 0.82714719
A12: Softmax Regression | B12: 1 | C12: 11 | D12: 0.70513021 | E12: 0.81228069
A13: Softmax Regression | B13: 1 | C13: 12 | D13: 0.68964321 | E13: 0.79925789
... A151: Softmax Regression | B151: 1 | C151: 150 | D151: 0.49246387 | E151: 0.66960376
A152: Softmax Regression | B152: 1 | C152: 151 | D152: 0.49231012 | E152: 0.66946571 | F152: x
A153: Softmax Regression | B153: 1 | C153: 152 | D153: 0.49216408 | E153: 0.66946531
A154: Softmax Regression | B154: 1 | C154: 153 | D154: 0.49205578 | E154: 0.66953886
A155: Softmax Regression | B155: 1 | C155: 154 | D155: 0.49193758 | E155: 0.66956933
A156: Softmax Regression | B156: 1 | C156: 155 | D156: 0.49181095 | E156: 0.66976249
A157: Softmax Regression | B157: 1 | C157: 156 | D157: 0.4916722 | E157: 0.66967829
A158: Softmax Regression | B158: 1 | C158: 157 | D158: 0.49154428 | E158: 0.66981189
A159: Softmax Regression | B159: 1 | C159: 158 | D159: 0.49139613 | E159: 0.66996783
A160: Softmax Regression | B160: 1 | C160: 159 | D160: 0.49124686 | E160: 0.66983928
A161: Softmax Regression | B161: 1 | C161: 160 | D161: 0.49110888 | E161: 0.66997616
A162: Softmax Regression | B162: 1 | C162: 161 | D162: 0.49096215 | E162: 0.66998887
A163: Softmax Regression | B163: 1 | C163: 162 | D163: 0.49085192 | E163: 0.67000875
A164: Softmax Regression | B164: 1 | C164: 163 | D164: 0.49071735 | E164: 0.67001556
... A577: XGBoost | B577: 1 | C577: 410 | D577: 0.019145217 | E577: 0.60828285
A578: XGBoost | B578: 1 | C578: 411 | D578: 0.019086984 | E578: 0.60794641 | F578: x
A579: XGBoost | B579: 1 | C579: 412 | D579: 0.019034395 | E579: 0.60809035
A580: XGBoost | B580: 1 | C580: 413 | D580: 0.018978178 | E580: 0.60841578
A581: XGBoost | B581: 1 | C581: 414 | D581: 0.018928658 | E581: 0.60843724
A582: XGBoost | B582: 1 | C582: 415 | D582: 0.018881054 | E582: 0.60862371
A583: XGBoost | B583: 1 | C583: 416 | D583: 0.018821696 | E583: 0.60853171
A584: XGBoost | B584: 1 | C584: 417 | D584: 0.018775071 | E584: 0.60851598
A585: XGBoost | B585: 1 | C585: 418 | D585: 0.018712055 | E585: 0.60871924
A586: XGBoost | B586: 1 | C586: 419 | D586: 0.018657448 | E586: 0.6085781
A587: XGBoost | B587: 1 | C587: 420 | D587: 0.018601872 | E587: 0.60861654
A588: XGBoost | B588: 1 | C588: 421 | D588: 0.018550785 | E588: 0.608792
A589: XGBoost | B589: 1 | C589: 422 | D589: 0.018501092 | E589: 0.60870021
...

Sheet Du_lieu_tung_lan
A1: Lần chạy | B1: Seed | C1: Tập | D1: Lớp | E1: Nguồn | F1: Số ảnh
A2: 1 | B2: 0 | C2: train | D2: giay | E2: realwaste | F2: 189
A3: 1 | B3: 0 | C3: train | D3: giay | E3: tu_chup | F3: 125
A4: 1 | B4: 0 | C4: train | D4: huu_co | E4: realwaste | F4: 208
A5: 1 | B5: 0 | C5: train | D5: huu_co | E5: tu_chup | F5: 105
A6: 1 | B6: 0 | C6: train | D6: khac | E6: realwaste | F6: 181
A7: 1 | B7: 0 | C7: train | D7: khac | E7: tu_chup | F7: 123
A8: 1 | B8: 0 | C8: train | D8: kim_loai | E8: realwaste | F8: 168
A9: 1 | B9: 0 | C9: train | D9: kim_loai | E9: tu_chup | F9: 138
A10: 1 | B10: 0 | C10: train | D10: nhua | E10: realwaste | F10: 66
A11: 1 | B11: 0 | C11: train | D11: nhua | E11: tu_chup | F11: 246
A12: 1 | B12: 0 | C12: val | D12: giay | E12: realwaste | F12: 40
A13: 1 | B13: 0 | C13: val | D13: giay | E13: tu_chup | F13: 27
... A151: 5 | B151: 4 | C151: test | D151: nhua | E151: tu_chup | F151: 53

Sheet Cau_hinh
A1: Tham số | B1: Giá trị
A2: Tổng số ảnh dùng | B2: 2213
A3: Số lần chạy | B3: 5
A4: Seed các lần | B4: 0, 1, 2, 3, 4
A5: Seed chọn ảnh | B5: 42
A6: Tỉ lệ train / val / test | B6: 70% / 15% / 15%
A7: Trích đặc trưng | B7: ResNet18 (ImageNet), 512 chiều
A8: Phần A: số chiều PCA thử | B8: [32, 64, 128, 256, 512]
A9: Phần A: siêu tham số mặc định | B9: Softmax Regression: penalty=l2, alpha=0.001, eta0=0.001; SVM: kernel=rbf, C=10, gamma=scale; XGBoost: max_depth=5, learning_rate=0.05, subsample=0.7, colsample_bytree=0.5
A10: Số chiều dùng cho phần B, C | B10: StandardScaler + PCA 128 chiều, fit trên train từng lần
A11: Softmax: lưới | B11: {'penalty': ['l2', 'l1'], 'alpha': [1e-05, 0.0001, 0.001, 0.01, 0.1], 'eta0': [0.0001, 0.001, 0.01]}
A12: Softmax: epoch tối đa / patience | B12: 200 / 15
A13: SVM: lưới | B13: {'kernel': ['linear', 'rbf'], 'C': [0.1, 1, 10, 100, 1000], 'gamma': ['scale', 0.0001, 0.001, 0.01, 0.1]}
A14: XGBoost: lưới | B14: {'max_depth': [3, 5, 7], 'learning_rate': [0.05, 0.1, 0.3], 'subsample': [0.7, 1.0], 'colsample_bytree': [0.5, 1.0]}
A15: XGBoost: vòng tối đa / early stopping | B15: 2000 / 50
A16: XGBoost: cố định | B16: min_child_weight 2, reg_lambda 1
A17: Số tổ hợp thử mỗi lần chạy | B17: {'Softmax Regression': 30, 'SVM': 30, 'XGBoost': 36}
... A22: Máy | B22: Windows-11-10.0.26200-SP0; CPU AMD64 Family 25 Model 80 Stepping 0, AuthenticAMD; GPU không
